Workbook
Name OLE_LINK2: '1'!#REF!

Sheet 1
B1: 会話第14課 | J1: 日付
B2: 名前 | L2: 学籍番号
B4: 問題1 １）～５）の初めに掲げる単語と声調の組み合わせが同じであるものを①～④の中からそれぞれ選びなさい。
C5: 答え： | H5: 1) | I5: 清华 | L5: ①咖啡 ②当然 ③翻译 ④开始
C6: 答え： | H6: 2） | I6: 庆祝 | L6: ①怎么 ②宿舍 ③可以 ④找人
C7: 答え： | H7: 3） | I7: 转告 | L7: ①以后 ②回家 ③词典 ④白天
C8: 答え： | H8: 4） | I8: 放心 | L8: ①留学 ②告诉 ③衬衣 ④小心
C9: 答え： | H9: 5） | I9: 商量 | L9: ①学校 ②妈妈 ③今年 ④麻烦
B11: 問題2 １）～５）の対となる会話文としてA～Eの中からもっとも適切なものを選び、その番号を括弧に入れなさい。
C12: 答え： | H12: 1) | I12: 喂，是清华大学留学生宿舍楼吗？
C13: 答え： | H13: 2） | I13: 我找你有点儿事，你能来一下吗？
C14: 答え： | H14: 3） | I14: 麻烦您叫好美接一下电话，好吗？
C15: 答え： | H15: 4） | I15: 你能转告他我给他去电话了吗？
C16: 答え： | H16: 5） | I16: 昨天我给你打电话，你不在。
E17: 1 | F17: 请等一下，我这就去叫她。 | P17: 2 | Q17: 对不起，我去商店买东西了。 | AA17: 5 | AB17: 对，你找谁？
E18: 3 | F18: 没问题，我这就去。 | P18: 4 | Q18: 好，放心吧。
B19: 問題3 中国語を聞き、１）～５）に対する答えとして最も適切なものを①～④から１つ選びなさい。
C20: 答え： | I20: 1) | J20: ① 对，我是留学生。 ② 对，是北大留学生楼。
J21: ③ 对，是北京大学。 ④ 对，是清华大学。
C23: 答え： | I23: 2） | J23: ① 我是杉山。 ② 我找铃木好美。
J24: ③ 我叫铃木好美。 ④ 我在找一个学生。
C26: 答え： | I26: 3） | J26: ① 明天晚上好。 ② 还是明天吧。
J27: ③ 还是后天吧。 ④ 后天不行。
C29: 答え： | I29: 4） | J29: ① 没关系。 ② 我喜欢看书。
J30: ③ 不客气。 ④ 谢谢。
C32: 答え： | I32: 5） | J32: ① 在学校做作业了。 ② 在家做作业了。
J33: ③ 踢足球了。 ④ 打网球了。
B35: 問題４ それぞれの録音と会話となっている文をA～Eの中から選び、その番号を括弧に入れるほか、録音の内容を下線の上に書きなさい。
B36: 1 | C36: 答え： | H36: 本文
B38: 2 | C38: 答え： | H38: 本文
B40: 3 | C40: 答え： | H40: 本文
B42: 4 | C42: 答え： | H42: 本文
B44: 5 | C44: 答え： | H44: 本文
C45: 1 | D45: 真的？那咱们给她好好儿祝贺祝贺。 | Q45: 2 | R45: 如果你现在有时间，我这就去。 | AC45: 5 | AD45: 我的分机号是 322，你打分机号就行。
C46: 3 | D46: 没问题，稍等，我这就去叫她。 | Q46: 4 | R46: 没问题，你什么时候有时间？
B48: 問題５ 下の選択肢の中からもっとも適切なものを選んで、下の各文の下線の上に入れない｡
K49: 还 还是 就 | P49: 这就 给 把
C50: 答え： | K50: 1 | L50: 你 | P50: 想再吃点什么？
C51: 答え： | K51: 2 | L51: 昨天我 | R51: 妈妈打电话了。
C52: 答え： | K52: 3 | L52: 昨天我 | R52: 妈妈的电话拿来了。
...

Sheet 2
B3: 日付 | C3: ='1'!L1 -> 0 | Q3: 判定 | U3: 成績
B4: 名前 | C4: ='1'!E2 -> 0 | J4: 正解
B5: 学籍番号 | C5: ='1'!N2 -> 0
E8: 問題１ | F8: 1 | G8: ='1'!E5 -> 0 | J8: 問題１ | K8: 1 | L8: ② | Q8: =IF(G8=L8,"〇","×") -> × | U8: =IF(Q8="〇",2,0) -> 0
F9: 2 | G9: ='1'!E6 -> 0 | K9: 2 | L9: ② | Q9: =IF(G9=L9,"〇","×") -> × | U9: =IF(Q9="〇",2,0) -> 0
F10: 3 | G10: ='1'!E7 -> 0 | K10: 3 | L10: ① | Q10: =IF(G10=L10,"〇","×") -> × | U10: =IF(Q10="〇",2,0) -> 0
F11: 4 | G11: ='1'!E8 -> 0 | K11: 4 | L11: ③ | Q11: =IF(G11=L11,"〇","×") -> × | U11: =IF(Q11="〇",2,0) -> 0
F12: 5 | G12: ='1'!E9 -> 0 | K12: 5 | L12: ② | Q12: =IF(G12=L12,"〇","×") -> × | U12: =IF(Q12="〇",2,0) -> 0
E15: 問題２ | F15: 1 | G15: ='1'!E12 -> 0 | J15: 問題２ | K15: 1 | L15: 5 | Q15: =IF(G15=L15,"〇","×") -> × | U15: =IF(Q15="〇",2,0) -> 0
F16: 2 | G16: ='1'!E13 -> 0 | K16: 2 | L16: 3 | Q16: =IF(G16=L16,"〇","×") -> × | U16: =IF(Q16="〇",2,0) -> 0
F17: 3 | G17: ='1'!E14 -> 0 | K17: 3 | L17: 1 | Q17: =IF(G17=L17,"〇","×") -> × | U17: =IF(Q17="〇",2,0) -> 0
F18: 4 | G18: ='1'!E15 -> 0 | K18: 4 | L18: 4 | Q18: =IF(G18=L18,"〇","×") -> × | U18: =IF(Q18="〇",2,0) -> 0
F19: 5 | G19: ='1'!E16 -> 0 | K19: 5 | L19: 2 | Q19: =IF(G19=L19,"〇","×") -> × | U19: =IF(Q19="〇",2,0) -> 0
E22: 問題３ | F22: 1 | G22: ='1'!E20 -> 0 | J22: 問題３ | K22: 1 | L22: ② | Q22: =IF(G22=L22,"〇","×") -> × | U22: =IF(Q22="〇",2,0) -> 0
F23: 2 | G23: ='1'!E23 -> 0 | K23: 2 | L23: ② | Q23: =IF(G23=L23,"〇","×") -> × | U23: =IF(Q23="〇",2,0) -> 0
F24: 3 | G24: ='1'!E26 -> 0 | K24: 3 | L24: ③ | Q24: =IF(G24=L24,"〇","×") -> × | U24: =IF(Q24="〇",2,0) -> 0
F25: 4 | G25: ='1'!E29 -> 0 | K25: 4 | L25: ④ | Q25: =IF(G25=L25,"〇","×") -> × | U25: =IF(Q25="〇",2,0) -> 0
F26: 5 | G26: ='1'!E32 -> 0 | K26: 5 | L26: ② | Q26: =IF(G26=L26,"〇","×") -> × | U26: =IF(Q26="〇",2,0) -> 0
E29: 問題４ | F29: 1 | G29: ='1'!E36 -> 0 | J29: 問題４ | K29: 1 | L29: 2 | M29: 你什么时候能来？ | Q29: =IF(G29=L29,"〇","×") -> × | U29: =IF(Q29="〇",4,0) -> 0
F30: 2 | G30: ='1'!E38 -> 0 | K30: 2 | L30: 3 | M30: 麻烦您叫好美接一下电话，好吗？ | Q30: =IF(AND(G30=L30)=TRUE,"〇","×") -> × | U30: =IF(Q30="〇",4,0) -> 0
F31: 3 | G31: ='1'!E40 -> 0 | K31: 3 | L31: 1 | M31: 下星期天是铃木十八岁的生日。 | Q31: =IF(AND(G31=L31)=TRUE,"〇","×") -> × | U31: =IF(Q31="〇",4,0) -> 0
F32: 4 | G32: ='1'!E42 -> 0 | K32: 4 | L32: 4 | M32: 咱们见面商量一下儿怎么样？ | Q32: =IF(AND(G32=L32)=TRUE,"〇","×") -> × | U32: =IF(Q32="〇",4,0) -> 0
F33: 5 | G33: ='1'!E44 -> 0 | K33: 5 | L33: 5 | M33: 我怎么给你打电话呢？ | Q33: =IF(AND(G33=L33)=TRUE,"〇","×") -> × | U33: =IF(Q33="〇",4,0) -> 0
E36: 問題５ | F36: 1 | G36: ='1'!E50 -> 0 | J36: 問題５ | K36: 1 | L36: 还 | Q36: =IF(G36=L36,"〇","×") -> × | U36: =IF(Q36="〇",5,0) -> 0
F37: 2 | G37: ='1'!E51 -> 0 | K37: 2 | L37: 给 | Q37: =IF(G37=L37,"〇","×") -> × | U37: =IF(Q37="〇",5,0) -> 0
F38: 3 | G38: ='1'!E52 -> 0 | K38: 3 | L38: 把 | Q38: =IF(G38=L38,"〇","×") -> × | U38: =IF(Q38="〇",5,0) -> 0
F39: 4 | G39: ='1'!E53 -> 0 | K39: 4 | L39: 还是 | Q39: =IF(G39=L39,"〇","×") -> × | U39: =IF(Q39="〇",5,0) -> 0
F40: 5 | G40: ='1'!E54 -> 0 | K40: 5 | L40: 这就 | Q40: =IF(G40=L40,"〇","×") -> × | U40: =IF(Q40="〇",5,0) -> 0
F41: 6 | G41: ='1'!E55 -> 0 | K41: 6 | L41: 就 | Q41: =IF(G41=L41,"〇","×") -> × | U41: =IF(Q41="〇",5,0) -> 0
E44: 問題６ | F44: 1 | G44: ='1'!C61 -> 0 | J44: 問題６ | K44: 1 | L44: 明天是小李的生日，大家给他好好儿庆祝庆祝。 | Q44: =IF(G44=L44,"〇","×") -> × | U44: =IF(Q44="〇",4,0) -> 0
F45: 2 | G45: ='1'!C64 -> 0 | K45: 2 | L45: 你还是不要去了吧。 | Q45: =IF(G45=L45,"〇","×") -> × | U45: =IF(Q45="〇",4,0) -> 0
F46: 3 | G46: ='1'!C67 -> 0 | H46: ='1'!C68 -> 0 | K46: 3 | L46: 喂，是南京大学留学生楼吗？ | N46: 是，您找谁？ | Q46: =IF(AND(G46=L46,H46=N46)=TRUE,"〇","×") -> × | U46: =IF(Q46="〇",4,0) -> 0
F47: 4 | G47: ='1'!C71 -> 0 | K47: 4 | L47: 这本书让我看看，好吗？ | Q47: =IF(G47=L46,"〇","×") -> × | U47: =IF(Q47="〇",4,0) -> 0
F48: 5 | G48: ='1'!C74 -> 0 | K48: 5 | L48: 他在那儿等你呢，你去好了。 | Q48: =IF(G48=L48,"〇","×") -> × | U48: =IF(Q48="〇",4,0) -> 0
Q54: 成績 | U54: =SUM(U8:U53) -> 0

Sheet 3
K3: 成績
C4: 日付 | D4: ='2'!C3 -> 0
C5: 名前 | D5: ='2'!C4 -> 0
C6: 学籍番号 | D6: ='2'!C5 -> 0 | I6: 問題１ | J6: 1 | K6: ='2'!Q8 -> ×
I7: 0.1 | J7: 2 | K7: ='2'!Q9 -> ×
J8: 3 | K8: ='2'!Q10 -> ×
J9: 4 | K9: ='2'!Q11 -> ×
C10: 成績 | D10: ='2'!U54 -> 0 | J10: 5 | K10: ='2'!Q12 -> ×
I13: 問題２ | J13: 1 | K13: ='2'!Q15 -> ×
I14: 0.1 | J14: 2 | K14: ='2'!Q16 -> ×
J15: 3 | K15: ='2'!Q17 -> ×
J16: 4 | K16: ='2'!Q18 -> ×
J17: 5 | K17: ='2'!Q19 -> ×
I20: 問題３ | J20: 1 | K20: ='2'!Q22 -> ×
I21: 0.1 | J21: 2 | K21: ='2'!Q23 -> ×
J22: 3 | K22: ='2'!Q24 -> ×
J23: 4 | K23: ='2'!Q25 -> ×
J24: 5 | K24: ='2'!Q26 -> ×
M26: 参考翻訳
I27: 問題４ | J27: 1 | K27: ='2'!Q29 -> × | M27: =IF(AND(K27="〇",K28="〇",K29="〇",K30="〇",K31="〇")=TRUE,'2'!M29,0) -> 0
I28: 0.2 | J28: 2 | K28: ='2'!Q30 -> × | M28: =IF(AND(K27="〇",K28="〇",K29="〇",K30="〇",K31="〇")=TRUE,'2'!M30,0) -> 0
J29: 3 | K29: ='2'!Q31 -> × | M29: =IF(AND(K27="〇",K28="〇",K29="〇",K30="〇",K31="〇")=TRUE,'2'!M31,0) -> 0
J30: 4 | K30: ='2'!Q32 -> × | M30: =IF(AND(K27="〇",K28="〇",K29="〇",K30="〇",K31="〇")=TRUE,'2'!M32,0) -> 0
J31: 5 | K31: ='2'!Q33 -> × | M31: =IF(AND(K27="〇",K28="〇",K29="〇",K30="〇",K31="〇")=TRUE,'2'!M33,0) -> 0
I34: 問題５ | J34: 1 | K34: ='2'!Q36 -> ×
I35: 0.3 | J35: 2 | K35: ='2'!Q37 -> ×
J36: 3 | K36: ='2'!Q38 -> ×
J37: 4 | K37: ='2'!Q39 -> ×
J38: 5 | K38: ='2'!Q40 -> ×
J39: 6 | K39: ='2'!Q41 -> ×
I42: 問題６ | J42: 1 | K42: ='2'!Q44 -> ×
I43: 0.2 | J43: 2 | K43: ='2'!Q45 -> ×
J44: 3 | K44: ='2'!Q46 -> ×
J45: 4 | K45: ='2'!Q47 -> ×
J46: 5 | K46: ='2'!Q48 -> ×
