Workbook

Sheet 1
B1: 会話第5課 | J1: 日付
B2: 名前 | L2: 学籍番号
B3: 問題２ 発音を聞いて、声調記号を付けなさい
C5: leng | F5: yuan | I5: kuai | L5: man | O5: huai | R5: pang | U5: shou | X5: gao | AA5: di | AD5: jin
C6: 冷 | F6: 远 | I6: 快 | L6: 慢 | O6: 坏 | R6: 胖 | U6: 瘦 | X6: 高 | AA6: 低 | AD6: 近
B9: 問題３ どちらかを発音するので、読まれた方に○をつけなさい。
B10: 1 | C10: kuài | F10: 1 | G10: mǎi | J10: 1 | K10: zhè | N10: 1 | O10: zuò | R10: 1 | S10: zài
B11: 2 | C11: huài | F11: 2 | G11: nǎi | J11: 2 | K11: rè | N11: 2 | O11: cuò | R11: 2 | S11: cài
B13: 問題４“有・在・想”の中から適切なものを選んで、下の各文の下線の 上に入れなさい｡
B14: 1 | K14: 我( )两本中文词典。
B15: 2 | K15: 我（ ）学校学习中文。
B16: 3 | K16: 我（ ）去中国学习中文。
B17: 4 | K17: 老师，星期天您（ ）学校做什么？
B18: 5 | K18: 桌子上（ ）一本中文词典。
B19: 問題５ 聞いた内容を漢字またはピンインで穴埋めしてから、日本語に訳しなさい。
B20: 1 | E20: 请问，（ ）的天气怎么样？
D22: 答え
D23: 翻訳
B24: 2 | E24: 你现在忙( )？
D26: 答え
D27: 翻訳
B28: 3 | E28: 请坐，请（ ）。
D30: 答え
D31: 翻訳
B32: 4 | E32: 今年暑假（ ）都想去南京，你呢？
D34: 答え
D35: 翻訳
B36: 5 | E36: 今天我想和（ ）去公园。 这是( )还是( )?
D38: 答え
D39: 翻訳
B40: 問題６ 次の文を中国語に訳しなさい。
B41: 1 | C41: 私は中国へ行きたい。
B43: 2 | C43: 私はお茶が飲みたい。
B45: 3 | C45: 私たちの大学は大きい。
B47: 4 | C47: 南京の夏はとても暑い。
B49: 5 | C49: 中国語はあまり難しくない。
B51: 問題７ 次のような場合に最も適切な中国語の表現をひとつ選びなさい。
B52: 1 | C52: お茶をすすめるとき | U52: 答え
C53: A | D53: Qǐng hē chá | N53: B | O53: Qǐng hē kāfēi
C54: C | D54: Qǐng chōu yān | N54: D | O54: Bié kèqi
...

Sheet 2
B2: 日付 | C2: ='[1]1'!L1 -> 0
B3: 名前 | C3: ='[1]1'!E2 -> 0
B4: 学籍番号 | C4: ='[1]1'!N2 -> 0 | J4: 正解 | N4: 回答 | P4: 点数
A6: 問題２ | B6: 1 | C6: ='1'!C5 -> leng | J6: le3ng | N6: =IF(C6=J6,"〇","×") -> × | P6: =IF(N6="〇",2,0) -> 0
B7: 2 | C7: ='1'!F5 -> yuan | J7: yua3n | N7: =IF(C7=J7,"〇","×") -> × | P7: =IF(N7="〇",2,0) -> 0
B8: 3 | C8: ='1'!I5 -> kuai | J8: kua4i | N8: =IF(C8=J8,"〇","×") -> × | P8: =IF(N8="〇",2,0) -> 0
B9: 4 | C9: ='1'!L5 -> man | J9: ma4n | N9: =IF(C9=J9,"〇","×") -> × | P9: =IF(N9="〇",2,0) -> 0
B10: 5 | C10: ='1'!O5 -> huai | J10: hua4i | N10: =IF(C10=J10,"〇","×") -> × | P10: =IF(N10="〇",2,0) -> 0
B11: 6 | C11: ='1'!R5 -> pang | J11: pa4ng | N11: =IF(C11=J11,"〇","×") -> × | P11: =IF(N11="〇",2,0) -> 0
B12: 7 | C12: ='1'!U5 -> shou | J12: sho4u | N12: =IF(C12=J12,"〇","×") -> × | P12: =IF(N12="〇",2,0) -> 0
B13: 8 | C13: ='1'!X5 -> gao | J13: ga1o | N13: =IF(C13=J13,"〇","×") -> × | P13: =IF(N13="〇",2,0) -> 0
B14: 9 | C14: ='1'!AA5 -> di | J14: di1 | N14: =IF(C14=J14,"〇","×") -> × | P14: =IF(N14="〇",2,0) -> 0
B15: 10 | C15: ='1'!AD5 -> jin | J15: ji4n | N15: =IF(C15=J15,"〇","×") -> × | P15: =IF(N15="〇",2,0) -> 0
A17: 問題３ | B17: 1 | C17: ='1'!B12 -> 0 | J17: 1 | N17: =IF(C17=J17,"〇","×") -> × | P17: =IF(N17="〇",2,0) -> 0
B18: 2 | C18: ='1'!F12 -> 0 | J18: 1 | N18: =IF(C18=J18,"〇","×") -> × | P18: =IF(N18="〇",2,0) -> 0
B19: 3 | C19: ='1'!J12 -> 0 | J19: 1 | N19: =IF(C19=J19,"〇","×") -> × | P19: =IF(N19="〇",2,0) -> 0
B20: 4 | C20: ='1'!N12 -> 0 | J20: 1 | N20: =IF(C20=J20,"〇","×") -> × | P20: =IF(N20="〇",2,0) -> 0
B21: 5 | C21: ='1'!R12 -> 0 | J21: 2 | N21: =IF(C21=J21,"〇","×") -> × | P21: =IF(N21="〇",2,0) -> 0
A23: 問題４ | B23: 1 | C23: ='1'!D14 -> 0 | J23: 有 | N23: =IF(C23=J23,"〇","×") -> × | P23: =IF(N23="〇",2,0) -> 0
B24: 2 | C24: ='1'!D15 -> 0 | J24: 在 | N24: =IF(C24=J24,"〇","×") -> × | P24: =IF(N24="〇",2,0) -> 0
B25: 3 | C25: ='1'!D16 -> 0 | J25: 想 | N25: =IF(C25=J25,"〇","×") -> × | P25: =IF(N25="〇",2,0) -> 0
B26: 4 | C26: ='1'!D17 -> 0 | J26: 在 | N26: =IF(C26=J26,"〇","×") -> × | P26: =IF(N26="〇",2,0) -> 0
B27: 5 | C27: ='1'!D18 -> 0 | J27: 有 | N27: =IF(C27=J27,"〇","×") -> × | P27: =IF(N27="〇",2,0) -> 0
A29: 問題５ | B29: 1 | C29: ='1'!G22 -> 0 | E29: ='1'!G23 -> 0 | J29: 明天 | L29: あのう、明日の天気はどうですか。 | N29: =IF(C29=J29,"〇","×") -> × | P29: =IF(N29="〇",5,0) -> 0
B30: 2 | C30: ='1'!G26 -> 0 | E30: ='1'!G27 -> 0 | J30: 不忙 | L30: あなたは今忙しいですか。 | N30: =IF(C30=J30,"〇","×") -> × | P30: =IF(N30="〇",5,0) -> 0
B31: 3 | C31: ='1'!G30 -> 0 | E31: ='1'!G31 -> 0 | J31: 喝茶 | L31: おかけください。お茶を飲んでください。 | N31: =IF(C31=J31,"〇","×") -> × | P31: =IF(N31="〇",5,0) -> 0
B32: 4 | C32: ='1'!G34 -> 0 | E32: ='1'!G35 -> 0 | J32: 我们 | L32: 今年の夏休み、私たちは南京に行きたいですが、あなたは。 | N32: =IF(C32=J32,"〇","×") -> × | P32: =IF(N32="〇",5,0) -> 0
B33: 5 | C33: ='1'!G38 -> 0 | E33: ='1'!G39 -> 0 | J33: 同学 | L33: 今日私はクラスメートと公園に行きたいです。 | N33: =IF(C33=J33,"〇","×") -> × | P33: =IF(N33="〇",5,0) -> 0
A36: 問題6 | B36: 1 | C36: ='1'!C42 -> 0 | J36: 我想去中国。 | N36: =IF(C36=J36,"〇","×") -> × | P36: =IF(N36="〇",5,0) -> 0
B37: 2 | C37: ='1'!C44 -> 0 | J37: 我想喝茶。 | N37: =IF(C37=J37,"〇","×") -> × | P37: =IF(N37="〇",5,0) -> 0
B38: 3 | C38: ='1'!C46 -> 0 | J38: 我们大学很大。 | N38: =IF(C38=J38,"〇","×") -> × | P38: =IF(N38="〇",5,0) -> 0
B39: 4 | C39: ='1'!C48 -> 0 | J39: 南京的夏天很热。 | N39: =IF(C39=J39,"〇","×") -> × | P39: =IF(N39="〇",5,0) -> 0
B40: 5 | C40: ='1'!C50 -> 0 | J40: 中文不太难。 | N40: =IF(C40=J40,"〇","×") -> × | P40: =IF(N40="〇",5,0) -> 0
A42: 問題7 | B42: 1 | C42: ='1'!W52 -> 0 | J42: A | N42: =IF(C42=J42,"〇","×") -> × | P42: =IF(N42="〇",2,0) -> 0
B43: 2 | C43: ='1'!W55 -> 0 | J43: A | N43: =IF(C43=J43,"〇","×") -> × | P43: =IF(N43="〇",2,0) -> 0
B44: 3 | C44: ='1'!W58 -> 0 | J44: A | N44: =IF(C44=J44,"〇","×") -> × | P44: =IF(N44="〇",2,0) -> 0
B45: 4 | C45: ='1'!W61 -> 0 | J45: D | N45: =IF(C45=J45,"〇","×") -> × | P45: =IF(N45="〇",2,0) -> 0
B46: 5 | C46: ='1'!W64 -> 0 | J46: A | N46: =IF(C46=J46,"〇","×") -> × | P46: =IF(N46="〇",2,0) -> 0
N53: 成績 | P53: =SUM(P6:P46) -> 0

Sheet 3
C2: 日付 | D2: ='1'!L1 -> 0 | H2: 回答
C3: 名前 | D3: ='1'!E2 -> 0
C4: 学籍番号 | D4: ='1'!N2 -> 0 | H4: 問題２ | I4: 1 | J4: ='2'!N6 -> ×
H5: 0.2 | I5: 2 | J5: ='2'!N7 -> ×
C6: 成績 | D6: ='2'!P53 -> 0 | I6: 3 | J6: ='2'!N8 -> ×
I7: 4 | J7: ='2'!N9 -> ×
I8: 5 | J8: ='2'!N10 -> ×
I9: 6 | J9: ='2'!N11 -> ×
I10: 7 | J10: ='2'!N12 -> ×
I11: 8 | J11: ='2'!N13 -> ×
I12: 9 | J12: ='2'!N14 -> ×
I13: 10 | J13: ='2'!N15 -> ×
H15: 問題３ | I15: 1 | J15: ='2'!N17 -> ×
H16: 0.1 | I16: 2 | J16: ='2'!N18 -> ×
I17: 3 | J17: ='2'!N19 -> ×
I18: 4 | J18: ='2'!N20 -> ×
I19: 5 | J19: ='2'!N21 -> ×
H21: 問題４ | I21: 1 | J21: ='2'!N23 -> ×
H22: 0.1 | I22: 2 | J22: ='2'!N24 -> ×
I23: 3 | J23: ='2'!N25 -> ×
I24: 4 | J24: ='2'!N26 -> ×
I25: 5 | J25: ='2'!N27 -> ×
L26: 参考翻訳
H27: 問題５ | I27: 1 | J27: ='2'!N29 -> × | L27: =IF(AND($J$27="〇",$J$28="〇",$J$29="〇",$J$30="〇",$J$31="〇")=TRUE,'2'!L29,0) -> 0
H28: 0.25 | I28: 2 | J28: ='2'!N30 -> × | L28: =IF(AND($J$27="〇",$J$28="〇",$J$29="〇",$J$30="〇",$J$31="〇")=TRUE,'2'!L30,0) -> 0
I29: 3 | J29: ='2'!N31 -> × | L29: =IF(AND($J$27="〇",$J$28="〇",$J$29="〇",$J$30="〇",$J$31="〇")=TRUE,'2'!L31,0) -> 0
I30: 4 | J30: ='2'!N32 -> × | L30: =IF(AND($J$27="〇",$J$28="〇",$J$29="〇",$J$30="〇",$J$31="〇")=TRUE,'2'!L32,0) -> 0
I31: 5 | J31: ='2'!N33 -> × | L31: =IF(AND($J$27="〇",$J$28="〇",$J$29="〇",$J$30="〇",$J$31="〇")=TRUE,'2'!L33,0) -> 0
H34: 問題6 | I34: 1 | J34: ='2'!N36 -> ×
H35: 0.25 | I35: 2 | J35: ='2'!N37 -> ×
I36: 3 | J36: ='2'!N38 -> ×
I37: 4 | J37: ='2'!N39 -> ×
I38: 5 | J38: ='2'!N40 -> ×
H40: 問題7 | I40: 1 | J40: ='2'!N42 -> ×
H41: 0.1 | I41: 2 | J41: ='2'!N43 -> ×
I42: 3 | J42: ='2'!N44 -> ×
I43: 4 | J43: ='2'!N45 -> ×
I44: 5 | J44: ='2'!N46 -> ×
