Workbook

Sheet 1
C1: 読解第4課 | P1: 日付
C2: 名前 | P2: 学籍番号
B3: 問１ 次の漢字の上に“拼音”をつけなさい。
D5: 出门 | H5: 起床 | L5: 开始 | P5: 结束 | T5: 回家
D7: 同学 | H7: 教室 | L7: 食堂 | P7: 每天 | T7: 学校
B8: 問２ 日本語の意味として正しい中国語を1)～4)の中から1つ選びなさい。
C9: 1 | D9: 夏休みは７月20日から始まる。 | S9: 答え
D10: Ａ | E10: 暑假7月20日从开始。 | O10: Ｂ | P10: 暑假从7月20日开始。
D11: Ｃ | E11: 从暑假7月20日开始。 | O11: Ｄ | P11: 从7月20日开始暑假。
C12: 2 | D12: きみは家で夕食（晚饭）を食べるか。 | S12: 答え
D13: Ａ | E13: 你家在吃晚饭吗？ | O13: Ｂ | P13: 你吃晚饭在家吗？
D14: Ｃ | E14: 你家在晚饭吃吗？ | O14: Ｄ | P14: 你在家吃晚饭吗？
C15: 3 | D15: 私は毎日六時半に起きる。 | S15: 答え
D16: Ａ | E16: 我每天起床6点半。 | O16: Ｂ | P16: 我6点半每天起床。
D17: Ｃ | E17: 我每天6点半起床。 | O17: Ｄ | P17: 我起床每天6点半。
C18: 4 | D18: 私は食堂へご飯を食べに行く。 | S18: 答え
D19: Ａ | E19: 我去食堂吃饭。 | O19: Ｂ | P19: 我食堂去吃饭。
D20: Ｃ | E20: 我吃饭食堂去。 | O20: Ｄ | P20: 我吃饭去食堂。
C21: 5 | D21: 中国語の授業は９時から11時までである。 | S21: 答え
D22: Ａ | E22: 从9点到11点中文课。 | O22: Ｂ | P22: 中文课9点从11点到。
D23: Ｃ | E23: 中文课到9点从11点。 | O23: Ｄ | P23: 中文课从9点到11点。
B24: 問３ 次の日本語の意味に従って、言葉を並べ替えなさい。
C25: 1 | D25: 山田さんは毎日七時に起きる。
D26: 每天 起床 七点 山田
D27: 答え
C28: 2 | D28: 彼女は毎日七時半に朝ご飯を食べる。
D29: 早饭 七点半 吃 她 每天
D30: 答え
C31: 3 | D31: 私は毎日９時から12時まで学校にいる。
D32: 从 到 每天 我 学校 在 9点 12点
D33: 答え
C34: 4 | D34: 英語の授業は何時から始まるか。
D35: 几点 课 从 开始 英文
D36: 答え
C37: 5 | D37: ３限目の授業は二時五十分に終わる。
D38: 结束 十分 第三节 三点 课 差
D39: 答え
C40: 6 | D40: 私は学校へ中国語を勉強しに行く。
D41: 中文 去 学习 学校 我
D42: 答え
...

Sheet 2
C1: 回答 | E1: 正解 | G1: 判定
B2: 問１
B3: 1 | C3: ='1'!D4 -> 0 | E3: chu1me2n | G3: =IF(C3=E3,2,0) -> 0
B4: 2 | C4: ='1'!H4 -> 0 | E4: qi3chua2ng | G4: =IF(C4=E4,2,0) -> 0
B5: 3 | C5: ='1'!L4 -> 0 | E5: ka1ishi3 | G5: =IF(C5=E5,2,0) -> 0
B6: 4 | C6: ='1'!P4 -> 0 | E6: jie2shu4 | G6: =IF(C6=E6,2,0) -> 0
B7: 5 | C7: ='1'!T4 -> 0 | E7: hui2jia1 | G7: =IF(C7=E7,2,0) -> 0
B8: 6 | C8: ='1'!D6 -> 0 | E8: to2ngxue2 | G8: =IF(C8=E8,2,0) -> 0
B9: 7 | C9: ='1'!H6 -> 0 | E9: jia4oshi4 | G9: =IF(C9=E9,2,0) -> 0
B10: 8 | C10: ='1'!L6 -> 0 | E10: shi2ta2ng | G10: =IF(C10=E10,2,0) -> 0
B11: 9 | C11: ='1'!P6 -> 0 | E11: me3itia1n | G11: =IF(C11=E11,2,0) -> 0
B12: 10 | C12: ='1'!T6 -> 0 | E12: xue2xia4o | G12: =IF(C12=E12,2,0) -> 0
B14: 問２
B15: 1 | C15: ='1'!U9 -> 0 | E15: B | G15: =IF(C15=E15,3,0) -> 0
B16: 2 | C16: ='1'!U12 -> 0 | E16: D | G16: =IF(C16=E16,3,0) -> 0
B17: 3 | C17: ='1'!U15 -> 0 | E17: C | G17: =IF(C17=E17,3,0) -> 0
B18: 4 | C18: ='1'!U18 -> 0 | E18: A | G18: =IF(C18=E18,3,0) -> 0
B19: 5 | C19: ='1'!U21 -> 0 | E19: D | G19: =IF(C19=E19,3,0) -> 0
B21: 問３
B22: 1 | C22: ='1'!F27 -> 0 | E22: 山田每天七点起床。 | G22: =IF(C22=E22,5,0) -> 0
B23: 2 | C23: ='1'!F30 -> 0 | E23: 她每天七点半吃早饭。 | G23: =IF(C23=E23,5,0) -> 0
B24: 3 | C24: ='1'!F33 -> 0 | E24: 我每天从9点到12点在学校。 | G24: =IF(C24=E24,5,0) -> 0
B25: 4 | C25: ='1'!F36 -> 0 | E25: 英文课从几点开始？ | G25: =IF(C25=E25,5,0) -> 0
B26: 5 | C26: ='1'!F39 -> 0 | E26: 第三节课差十分三点结束。 | G26: =IF(C26=E26,5,0) -> 0
B27: 6 | C27: ='1'!F42 -> 0 | E27: 我去学校学习中文。 | G27: =IF(C27=E27,5,0) -> 0
B28: 7 | C28: ='1'!F45 -> 0 | E28: 你在食堂吃午饭吗？ | G28: =IF(C28=E28,5,0) -> 0
B29: 8 | C29: ='1'!F48 -> 0 | E29: 有的同学听课，有的同学睡觉。 | G29: =IF(C29=E29,5,0) -> 0
B31: 問４
B32: 1 | C32: ='1'!F51 -> 0 | E32: 他晚上在家里吃晚饭。 | G32: =IF(C32=E32,5,0) -> 0
B33: 2 | C33: ='1'!F53 -> 0 | E33: 你每天六点回家吗？ | G33: =IF(C33=E33,5,0) -> 0
B34: 3 | C34: ='1'!F55 -> 0 | E34: 我们在教室吃午饭。 | G34: =IF(C34=E34,5,0) -> 0
B35: 4 | C35: ='1'!F57 -> 0 | E35: 我从九点到十二点在学校。 | G35: =IF(C35=E35,5,0) -> 0
B36: 5 | C36: ='1'!F59 -> 0 | E36: 明天山田不来学校。 | G36: =IF(C36=E36,5,0) -> 0
E42: 合計 | G42: =SUM(G3:G36) -> 0

Sheet 3
B2: 日付 | C2: ='1'!R1 -> 0 | H2: 判定
B3: 学籍番号 | C3: ='1'!S2 -> 0 | G3: 問１ | H3: 0.2
B4: 名前 | C4: ='1'!E2 -> 0 | G4: 1 | H4: =IF('2'!C3='2'!E3,"○","×") -> ×
G5: 2 | H5: =IF('2'!C4='2'!E4,"○","×") -> ×
C6: 成績 | E6: ='2'!G42 -> 0 | G6: 3 | H6: =IF('2'!C5='2'!E5,"○","×") -> ×
G7: 4 | H7: =IF('2'!C6='2'!E6,"○","×") -> ×
G8: 5 | H8: =IF('2'!C7='2'!E7,"○","×") -> ×
G9: 6 | H9: =IF('2'!C8='2'!E8,"○","×") -> ×
G10: 7 | H10: =IF('2'!C9='2'!E9,"○","×") -> ×
G11: 8 | H11: =IF('2'!C10='2'!E10,"○","×") -> ×
G12: 9 | H12: =IF('2'!C11='2'!E11,"○","×") -> ×
G13: 10 | H13: =IF('2'!C12='2'!E12,"○","×") -> ×
G15: 問２ | H15: 0.15
G16: 1 | H16: =IF('2'!C15='2'!E15,"○","×") -> ×
G17: 2 | H17: =IF('2'!C16='2'!E16,"○","×") -> ×
G18: 3 | H18: =IF('2'!C17='2'!E17,"○","×") -> ×
G19: 4 | H19: =IF('2'!C18='2'!E18,"○","×") -> ×
G20: 5 | H20: =IF('2'!C19='2'!E19,"○","×") -> ×
G22: 問３ | H22: 0.4
G23: 1 | H23: =IF('2'!C22='2'!E22,"○","×") -> ×
G24: 2 | H24: =IF('2'!C23='2'!E23,"○","×") -> ×
G25: 3 | H25: =IF('2'!C24='2'!E24,"○","×") -> ×
G26: 4 | H26: =IF('2'!C25='2'!E25,"○","×") -> ×
G27: 5 | H27: =IF('2'!C26='2'!E26,"○","×") -> ×
G28: 6 | H28: =IF('2'!C27='2'!E27,"○","×") -> ×
G29: 7 | H29: =IF('2'!C28='2'!E28,"○","×") -> ×
G30: 8 | H30: =IF('2'!C29='2'!E29,"○","×") -> ×
G32: 問４ | H32: 0.25
G33: 1 | H33: =IF('2'!C32='2'!E32,"○","×") -> ×
G34: 2 | H34: =IF('2'!C33='2'!E33,"○","×") -> ×
G35: 3 | H35: =IF('2'!C34='2'!E34,"○","×") -> ×
G36: 4 | H36: =IF('2'!C35='2'!E35,"○","×") -> ×
G37: 5 | H37: =IF('2'!C36='2'!E36,"○","×") -> ×
