Workbook
Name OLE_LINK2: '1'!#REF!

Sheet 1
B1: 読解第8課 | J1: 日付
B2: 名前 | L2: 学籍番号
B3: 問題1穴埋め問題の回答として、正しい中国語を1)～4)の中から1つ選びなさい。
C4: 答え | H4: ① | I4: 暑假你打算去哪儿（どこ）旅行 | X4: ？
I5: 1) 呢 2) 吗 3) 吧 4) 没
C6: 答え | H6: ② | I6: 你太累了，好好儿休息 | U6: 。
I7: 1) 呢 2) 吗 3) 吧 4) 没
C8: 答え | H8: ③ | I8: 你去 | N8: 去北京？
I9: 1) 呢 2) 吗 3) 吧 4) 没
C10: 答え | H10: ④ | I10: 他是日本人 | Q10: ？
I11: 1) 呢 2) 吗 3) 吧 4) 没
C12: 答え | H12: ⑤ | I12: 我想她一定是日本人 | T12: 。
I13: 1) 呢 2) 吗 3) 吧 4) 没
B14: 問題2 日本語の意味として正しい中国語を1)～4)の中から1つ選びなさい。
C15: 答え | H15: ① | I15: 私に生活が慣れたかどうかを聞いた。
I16: 1) 问我习惯不习惯生活。 2) 我问习惯不习惯生活。
I17: 3) 问我生活习惯不习惯。 4) 我不问习惯生活习惯。
C18: 答え | H18: ② | I18: 君に美味しい料理を作ってやろう。
I19: 1) 我给做好吃的菜你。 2) 你给我做好吃的菜。
I20: 3) 我给你好吃的菜做。 4) 我给你做好吃的菜。
C21: 答え | H21: ③ | I21: 私はその日ほんとうに幸せだと感じた。
I22: 1) 我觉得那天真幸福。 2) 我觉得真幸福那天。
I23: 3) 我真觉得幸福那天。 4) 我真觉得那天幸福。
C24: 答え | H24: ④ | I24: テーブルを囲んで一緒に食事をする。
I25: 1) 围着一起桌子吃饭。 2) 围着桌子一起吃饭。
I26: 3) 一起吃饭围着桌子。 4) 桌子围着一起吃饭。
C27: 答え | H27: ⑤ | I27: 彼女は何度も尋ねた。
I28: 1) 问了一遍又一遍她。 2) 她又问了一遍一遍。
I29: 3) 她问一遍又一遍了。 4) 她问了一遍又一遍。
B30: 問題3 次の日本語の意味に従って、言葉を並べ替えなさい。
C31: ① | D31: 私が帰ってきたのを見て、母と父はすごく嬉しかった。
D32: 回来 妈妈 爸爸 我 坏了 看到 高兴 和 了
C34: ② | D34: 彼らは私の手をひぱってあれこれと聞いた。
D35: 拉着 问 问 他们 我 这 那 的 手
C37: ③ | D37: お母さんは美味しい料理をたくさん作ってくれた。
D38: 好吃 做 给 了 我 妈妈 很多 的 菜
C40: ④ | D40: 夏休みはすでに終わった。私はまだ名古屋に戻ってきた。
D41: 回到了 结束 又 我 已经 名古屋 暑假 了
C43: ⑤ | D43: 私は家族の人と一緒に会話をする事をとても幸せだと思う｡
D44: 幸福 家里人 聊天儿 很 和 觉得 一起 我
...

Sheet 2
C1: 回答 | E1: 正解 | G1: 判定
B2: 問１
B3: 1 | C3: ='1'!E4 -> 0 | E3: 1 | G3: =IF(C3=E3,3,0) -> 0
B4: 2 | C4: ='1'!E6 -> 0 | E4: 3 | G4: =IF(C4=E4,3,0) -> 0
B5: 3 | C5: ='1'!E8 -> 0 | E5: 4 | G5: =IF(C5=E5,3,0) -> 0
B6: 4 | C6: ='1'!E10 -> 0 | E6: 2 | G6: =IF(C6=E6,3,0) -> 0
B7: 5 | C7: ='1'!E12 -> 0 | E7: 3 | G7: =IF(C7=E7,3,0) -> 0
B9: 問２
B10: 1 | C10: ='1'!E15 -> 0 | E10: 3 | G10: =IF(C10=E10,3,0) -> 0
B11: 2 | C11: ='1'!E18 -> 0 | E11: 4 | G11: =IF(C11=E11,3,0) -> 0
B12: 3 | C12: ='1'!E21 -> 0 | E12: 1 | G12: =IF(C12=E12,3,0) -> 0
B13: 4 | C13: ='1'!E24 -> 0 | E13: 2 | G13: =IF(C13=E13,3,0) -> 0
B14: 5 | C14: ='1'!E27 -> 0 | E14: 4 | G14: =IF(C14=E14,3,0) -> 0
B16: 問３
B17: 1 | C17: ='1'!C33 -> 0 | E17: 看到我回来了，爸爸和妈妈高兴坏了。 | G17: =IF(C17=E17,5,0) -> 0
B18: 2 | C18: ='1'!C36 -> 0 | E18: 他们拉着我的手问这问那。 | G18: =IF(C18=E18,5,0) -> 0
B19: 3 | C19: ='1'!C39 -> 0 | E19: 妈妈给我做了很多好吃的菜。 | G19: =IF(C19=E19,5,0) -> 0
B20: 4 | C20: ='1'!C42 -> 0 | E20: 暑假已经结束了，我又回到了名古屋。 | G20: =IF(C20=E20,5,0) -> 0
B21: 5 | C21: ='1'!C45 -> 0 | E21: 我觉得和家里人一起聊天儿很幸福。 | G21: =IF(C21=E21,5,0) -> 0
B22: 6 | C22: ='1'!C48 -> 0 | E22: 看到弟弟回来了，我高兴极了。 | G22: =IF(C22=E22,5,0) -> 0
B23: 7 | C23: ='1'!C51 -> 0 | E23: 我问弟弟大学的生活怎么样。 | G23: =IF(C23=E23,5,0) -> 0
B24: 8 | C24: ='1'!C54 -> 0 | E24: 今年暑假你去北京了没有？ | G24: =IF(C24=E24,5,0) -> 0
B26: 問４
B27: 1 | C27: ='1'!D58 -> 0 | E27: 我给弟弟买了很多好吃的点心。 | G27: =IF(C27=E27,3,0) -> 0
B28: 2 | C28: ='1'!D60 -> 0 | E28: 妈妈问了一遍又一遍。 | G28: =IF(C28=E28,3,0) -> 0
B29: 3 | C29: ='1'!D62 -> 0 | E29: 大学的生活已经结束了。 | G29: =IF(C29=E29,3,0) -> 0
B30: 4 | C30: ='1'!D64 -> 0 | E30: 奶奶问我一个人的生活习惯不习惯。 | G30: =IF(C30=E30,3,0) -> 0
B31: 5 | C31: ='1'!D66 -> 0 | E31: 爷爷拉着我的手问这问那。 | G31: =IF(C31=E31,3,0) -> 0
B33: 問5
B34: 1 | C34: ='1'!E70 -> 0 | E34: 4 | G34: =IF(C34=E34,3,0) -> 0
B35: 2 | C35: ='1'!E73 -> 0 | E35: 3 | G35: =IF(C35=E35,3,0) -> 0
B36: 3 | C36: ='1'!E76 -> 0 | E36: 2 | G36: =IF(C36=E36,3,0) -> 0
B37: 4 | C37: ='1'!E79 -> 0 | E37: 1 | G37: =IF(C37=E37,3,0) -> 0
B38: 5 | C38: ='1'!E82 -> 0 | E38: 1 | G38: =IF(C38=E38,3,0) -> 0
E46: 合計 | G46: =SUM(G2:G45) -> 0

Sheet 3
B2: 日付 | C2: ='1'!L1 -> 0 | H2: 判定
B3: 学籍番号 | C3: ='1'!N2 -> 0 | G3: 問１ | H3: 0.15
B4: 名前 | C4: ='1'!E2 -> 0 | G4: 1 | H4: =IF('2'!C3='2'!E3,"○","×") -> ×
G5: 2 | H5: =IF('2'!C4='2'!E4,"○","×") -> ×
C6: 成績 | E6: ='2'!G46 -> 0 | G6: 3 | H6: =IF('2'!C5='2'!E5,"○","×") -> ×
G7: 4 | H7: =IF('2'!C6='2'!E6,"○","×") -> ×
G8: 5 | H8: =IF('2'!C7='2'!E7,"○","×") -> ×
G10: 問２ | H10: 0.15
G11: 1 | H11: =IF('2'!C10='2'!E10,"○","×") -> ×
G12: 2 | H12: =IF('2'!C11='2'!E11,"○","×") -> ×
G13: 3 | H13: =IF('2'!C12='2'!E12,"○","×") -> ×
G14: 4 | H14: =IF('2'!C13='2'!E13,"○","×") -> ×
G15: 5 | H15: =IF('2'!C14='2'!E14,"○","×") -> ×
G17: 問３ | H17: 0.4
G18: 1 | H18: =IF('2'!C17='2'!E17,"○","×") -> ×
G19: 2 | H19: =IF('2'!C18='2'!E18,"○","×") -> ×
G20: 3 | H20: =IF('2'!C19='2'!E19,"○","×") -> ×
G21: 4 | H21: =IF('2'!C20='2'!E20,"○","×") -> ×
G22: 5 | H22: =IF('2'!C21='2'!E21,"○","×") -> ×
G23: 6 | H23: =IF('2'!C22='2'!E22,"○","×") -> ×
G24: 7 | H24: =IF('2'!C23='2'!E23,"○","×") -> ×
G25: 8 | H25: =IF('2'!C24='2'!E24,"○","×") -> ×
G27: 問４ | H27: 0.15
G28: 1 | H28: =IF('2'!C27='2'!E27,"○","×") -> ×
G29: 2 | H29: =IF('2'!C28='2'!E28,"○","×") -> ×
G30: 3 | H30: =IF('2'!C29='2'!E29,"○","×") -> ×
G31: 4 | H31: =IF('2'!C30='2'!E30,"○","×") -> ×
G32: 5 | H32: =IF('2'!C31='2'!E31,"○","×") -> ×
G34: 問5 | H34: 0.15
G35: 1 | H35: =IF('2'!C34='2'!E34,"○","×") -> ×
G36: 2 | H36: =IF('2'!C35='2'!E35,"○","×") -> ×
G37: 3 | H37: =IF('2'!C36='2'!E36,"○","×") -> ×
G38: 4 | H38: =IF('2'!C37='2'!E37,"○","×") -> ×
G39: 5 | H39: =IF('2'!C38='2'!E38,"○","×") -> ×
