Workbook
Name OLE_LINK2: '1'!$D$56

Sheet 1
B1: 会話第１課 | J1: 日付
B2: 名前 | L2: 学籍番号 | W2: 注： | X2: 録音をダブルクリックして、録音が再生します
B3: 問題２ 発音を聞いて、声調記号を付けなさい
C4: ba | F4: jie | I4: ge | L4: gui | O4: shu | R4: yi | U4: mei | X4: di | AA4: gu | AD4: nu
C5: ba | F5: jie | I5: ge | L5: gui | O5: shu | R5: yi | U5: mei | X5: di | AA5: gu | AD5: nu
C6: 爸 | F6: 姐 | I6: 哥 | L6: 贵 | O6: 叔 | R6: 姨 | U6: 妹 | X6: 弟 | AA6: 姑 | AD6: 奴
C7: 録音↑ | F7: 録音↑ | I7: 録音↑ | L7: 録音↑ | O7: 録音↑ | R7: 録音↑ | U7: 録音↑ | X7: 録音↑ | AA7: 録音↑ | AD7: 録音↑
B8: 問題３ どちらかを発音するので、読まれた方に○をつけなさい。
E9: 1 | F9: ō | H9: 1 | I9: yī | K9: 1 | L9: mǔ | N9: 1 | O9: ná | Q9: 1 | R9: bō
E10: 2 | F10: ē | H10: 2 | I10: yū | K10: 2 | L10: lǔ | N10: 2 | O10: lá | Q10: 2 | R10: pō
B12: 問題４ “姓,叫,是,不是”の中から適切なものを選んで、下の各文の下線の上に入れなさい。
B13: 答え | H13: 1 | I13: 我妈妈 | N13: 学生，是老师。
B14: 答え | H14: 2 | I14: 我 | N14: 山田爱子。
B15: 答え | H15: 3 | I15: 我妈妈 | N15: 张。
B16: 答え | H16: 4 | I16: 我 | N16: 爱知淑德大学大学的学生，不是爱知大学的学生。
B17: 答え | H17: 5 | I17: 我爸爸 | N17: 山田，妈妈 | S17: 张。
B19: 問題５ 聞いた内容を漢字で穴埋めしてから、日本語に訳しなさい。
B20: 1 | C20: 我 | G20: 山田， | N20: 山田爱子。
B22: 2 | I22: ，您贵姓？
B24: 3 | C24: 山田爱子学习 | M24: 。
B26: 4 | C26: 欢迎，欢迎， | M26: 。
B28: 5 | C28: 谢谢。 | M28: 。
B31: 問題６ 次の文を中国語に訳しなさい。
B32: 1 | C32: 私は愛知淑徳大学の学生です。
B34: 2 | C34: 先生、何とおっしゃいますか？
B36: 3 | C36: 私は張と申します。張華といいます。
B38: 4 | C38: ようこそ。おかけ下さい。
B40: 5 | C40: ありがとう。どういたしまして。
B44: 問題７ 次のような場合に最も適切な中国語の表現をひとつ選びなさい。
B45: 1 | C45: 自分のフルネームを言うとき | U45: 答え
C46: A | D46: Wǒ xìng Zhāng | N46: B | O46: Wǒ jiào Zhāng Huá
C47: C | D47: Wǒ māma xìng Zhāng | N47: D | O47: Wǒ māma jiào Zhāng Huá
B48: 2 | C48: 座るように人を進めるとき | U48: 答え
C49: A | D49: Qǐng hēchá | N49: B | O49: Qǐng jìn
C50: C | D50: Qǐng yuánliàng | N50: D | O50: Qǐng zuò
B51: 3 | C51: 人の到着を歓迎するとき | U51: 答え
C52: A | D52: Yílù píng’ān | N52: B | O52: Màn zǒu a
C53: C | D53: Huānyíng huānyíng | N53: D | O53: Dǎjiǎo nín le
B54: 4 | C54: 相手の名前を聞くとき | U54: 答え
C55: A | D55: Qǐngwèn nín guìxìng | N55: B | O55: Jīntiān xīngqījǐ
...

Sheet 2
B2: 日付 | C2: ='1'!L1 -> 0
B3: 名前 | C3: ='1'!E2 -> 0
B4: 学籍番号 | C4: ='1'!N2 -> 0 | J4: 正解 | N4: 回答 | P4: 点数
A6: 問題２ | B6: 1 | C6: ='1'!C4 -> ba | J6: ba4 | N6: =IF(C6=J6,"〇","×") -> × | P6: =IF(N6="〇",2,0) -> 0
B7: 2 | C7: ='1'!F4 -> jie | J7: jie3 | N7: =IF(C7=J7,"〇","×") -> × | P7: =IF(N7="〇",2,0) -> 0
B8: 3 | C8: ='1'!I4 -> ge | J8: ge1 | N8: =IF(C8=J8,"〇","×") -> × | P8: =IF(N8="〇",2,0) -> 0
B9: 4 | C9: ='1'!L4 -> gui | J9: gui4 | N9: =IF(C9=J9,"〇","×") -> × | P9: =IF(N9="〇",2,0) -> 0
B10: 5 | C10: ='1'!O4 -> shu | J10: shu1 | N10: =IF(C10=J10,"〇","×") -> × | P10: =IF(N10="〇",2,0) -> 0
B11: 6 | C11: ='1'!R4 -> yi | J11: yi2 | N11: =IF(C11=J11,"〇","×") -> × | P11: =IF(N11="〇",2,0) -> 0
B12: 7 | C12: ='1'!U4 -> mei | J12: me4i | N12: =IF(C12=J12,"〇","×") -> × | P12: =IF(N12="〇",2,0) -> 0
B13: 8 | C13: ='1'!X4 -> di | J13: di4 | N13: =IF(C13=J13,"〇","×") -> × | P13: =IF(N13="〇",2,0) -> 0
B14: 9 | C14: ='1'!AA4 -> gu | J14: gu1 | N14: =IF(C14=J14,"〇","×") -> × | P14: =IF(N14="〇",2,0) -> 0
B15: 10 | C15: ='1'!AD4 -> nu | J15: nu2 | N15: =IF(C15=J15,"〇","×") -> × | P15: =IF(N15="〇",2,0) -> 0
A17: 問題３ | B17: 1 | C17: ='1'!E11 -> 0 | J17: 2 | N17: =IF(C17=J17,"〇","×") -> × | P17: =IF(N17="〇",2,0) -> 0
B18: 2 | C18: ='1'!H11 -> 0 | J18: 2 | N18: =IF(C18=J18,"〇","×") -> × | P18: =IF(N18="〇",2,0) -> 0
B19: 3 | C19: ='1'!K11 -> 0 | J19: 1 | N19: =IF(C19=J19,"〇","×") -> × | P19: =IF(N19="〇",2,0) -> 0
B20: 4 | C20: ='1'!N11 -> 0 | J20: 2 | N20: =IF(C20=J20,"〇","×") -> × | P20: =IF(N20="〇",2,0) -> 0
B21: 5 | C21: ='1'!Q11 -> 0 | J21: 2 | N21: =IF(C21=J21,"〇","×") -> × | P21: =IF(N21="〇",2,0) -> 0
A23: 問題４ | B23: 1 | C23: ='1'!D13 -> 0 | J23: 不是 | N23: =IF(C23=J23,"〇","×") -> × | P23: =IF(N23="〇",2,0) -> 0
B24: 2 | C24: ='1'!D14 -> 0 | J24: 叫 | N24: =IF(C24=J24,"〇","×") -> × | P24: =IF(N24="〇",2,0) -> 0
B25: 3 | C25: ='1'!D15 -> 0 | J25: 姓 | N25: =IF(C25=J25,"〇","×") -> × | P25: =IF(N25="〇",2,0) -> 0
B26: 4 | C26: ='1'!D16 -> 0 | J26: 是 | N26: =IF(C26=J26,"〇","×") -> × | P26: =IF(N26="〇",2,0) -> 0
B27: 5 | C27: ='1'!D17 -> 0 | J27: 姓 | N27: =IF(C27=J27,"〇","×") -> × | P27: =IF(N27="〇",2,0) -> 0
A29: 問題５ | B29: 1 | C29: ='1'!D20 -> 0 | D29: ='1'!J20 -> 0 | E29: ='1'!D21 -> 0 | J29: 姓 | K29: 叫 | L29: 私の苗字は山田で、山田愛子と言います。 | N29: =IF(AND(C29=J29,D29=K29)=TRUE,"〇","×") -> × | P29: =IF(N29="〇",5,0) -> 0
B30: 2 | C30: ='1'!C22 -> 0 | E30: ='1'!D23 -> 0 | J30: 老师 | L30: 先生、なんとおっしゃいますか。 | N30: =IF(C30=J30,"〇","×") -> × | P30: =IF(N30="〇",5,0) -> 0
B31: 3 | C31: ='1'!I24 -> 0 | E31: ='1'!D25 -> 0 | J31: 中文 | L31: 山田愛子は中国語を勉強しています。 | N31: =IF(C31=J31,"〇","×") -> × | P31: =IF(N31="〇",5,0) -> 0
B32: 4 | C32: ='1'!I26 -> 0 | E32: ='1'!D27 -> 0 | J32: 请坐 | L32: ようこそ、おかけください。 | N32: =IF(C32=J32,"〇","×") -> × | P32: =IF(N32="〇",5,0) -> 0
B33: 5 | C33: ='1'!I28 -> 0 | E33: ='1'!D29 -> 0 | J33: 不客气 | L33: ありがとう、どいたしまして。 | N33: =IF(C33=J33,"〇","×") -> × | P33: =IF(N33="〇",5,0) -> 0
A36: 問題6 | B36: 1 | C36: ='1'!C33 -> 0 | J36: 我是爱知淑德大学的学生。 | N36: =IF(C36=J36,"〇","×") -> × | P36: =IF(N36="〇",5,0) -> 0
B37: 2 | C37: ='1'!C35 -> 0 | J37: 老师，您贵姓？ | N37: =IF(C37=J37,"〇","×") -> × | P37: =IF(N37="〇",5,0) -> 0
B38: 3 | C38: ='1'!C37 -> 0 | J38: 我姓张，叫张华。 | N38: =IF(C38=J38,"〇","×") -> × | P38: =IF(N38="〇",5,0) -> 0
B39: 4 | C39: ='1'!C39 -> 0 | J39: 欢迎欢迎，请坐。 | N39: =IF(C39=J39,"〇","×") -> × | P39: =IF(N39="〇",5,0) -> 0
B40: 5 | C40: ='1'!C41 -> 0 | J40: 谢谢，不客气。 | N40: =IF(C40=J40,"〇","×") -> × | P40: =IF(N40="〇",5,0) -> 0
A42: 問題7 | B42: 1 | C42: ='1'!W45 -> 0 | J42: B | N42: =IF(C42=J42,"〇","×") -> × | P42: =IF(N42="〇",2,0) -> 0
B43: 2 | C43: ='1'!W48 -> 0 | J43: D | N43: =IF(C43=J43,"〇","×") -> × | P43: =IF(N43="〇",2,0) -> 0
B44: 3 | C44: ='1'!W51 -> 0 | J44: C | N44: =IF(C44=J44,"〇","×") -> × | P44: =IF(N44="〇",2,0) -> 0
B45: 4 | C45: ='1'!W54 -> 0 | J45: A | N45: =IF(C45=J45,"〇","×") -> × | P45: =IF(N45="〇",2,0) -> 0
B46: 5 | C46: ='1'!W57 -> 0 | J46: C | N46: =IF(C46=J46,"〇","×") -> × | P46: =IF(N46="〇",2,0) -> 0
N53: 成績 | P53: =SUM(P6:P46) -> 0

Sheet 3
C2: 日付 | D2: ='2'!C2 -> 0 | H2: 回答
C3: 名前 | D3: ='2'!C3 -> 0
C4: 学籍番号 | D4: ='2'!C4 -> 0 | H4: 問題２ | I4: 1 | J4: ='2'!N6 -> ×
H5: 0.2 | I5: 2 | J5: ='2'!N7 -> ×
C6: 成績 | D6: ='2'!P53 -> 0 | I6: 3 | J6: ='2'!N8 -> ×
I7: 4 | J7: ='2'!N9 -> ×
I8: 5 | J8: ='2'!N10 -> ×
I9: 6 | J9: ='2'!N11 -> ×
I10: 7 | J10: ='2'!N12 -> ×
I11: 8 | J11: ='2'!N13 -> ×
I12: 9 | J12: ='2'!N14 -> ×
I13: 10 | J13: ='2'!N15 -> ×
H15: 問題３ | I15: 1 | J15: ='2'!N17 -> ×
H16: 0.1 | I16: 2 | J16: ='2'!N18 -> ×
I17: 3 | J17: ='2'!N19 -> ×
I18: 4 | J18: ='2'!N20 -> ×
I19: 5 | J19: ='2'!N21 -> ×
H21: 問題４ | I21: 1 | J21: ='2'!N23 -> ×
H22: 0.1 | I22: 2 | J22: ='2'!N24 -> ×
I23: 3 | J23: ='2'!N25 -> ×
I24: 4 | J24: ='2'!N26 -> ×
I25: 5 | J25: ='2'!N27 -> ×
L26: 参考翻訳
H27: 問題５ | I27: 1 | J27: ='2'!N29 -> × | L27: =IF(AND($J$27="〇",$J$28="〇",$J$29="〇",$J$30="〇",$J$31="〇")=TRUE,'[1]2'!L29,0) -> 0
H28: 0.25 | I28: 2 | J28: ='2'!N30 -> × | L28: =IF(AND($J$27="〇",$J$28="〇",$J$29="〇",$J$30="〇",$J$31="〇")=TRUE,'[1]2'!L30,0) -> 0
I29: 3 | J29: ='2'!N31 -> × | L29: =IF(AND($J$27="〇",$J$28="〇",$J$29="〇",$J$30="〇",$J$31="〇")=TRUE,'[1]2'!L31,0) -> 0
I30: 4 | J30: ='2'!N32 -> × | L30: =IF(AND($J$27="〇",$J$28="〇",$J$29="〇",$J$30="〇",$J$31="〇")=TRUE,'[1]2'!L32,0) -> 0
I31: 5 | J31: ='2'!N33 -> × | L31: =IF(AND($J$27="〇",$J$28="〇",$J$29="〇",$J$30="〇",$J$31="〇")=TRUE,'[1]2'!L33,0) -> 0
H34: 問題6 | I34: 1 | J34: ='2'!N36 -> ×
H35: 0.25 | I35: 2 | J35: ='2'!N37 -> ×
I36: 3 | J36: ='2'!N38 -> ×
I37: 4 | J37: ='2'!N39 -> ×
I38: 5 | J38: ='2'!N40 -> ×
H40: 問題7 | I40: 1 | J40: ='2'!N42 -> ×
H41: 0.1 | I41: 2 | J41: ='2'!N43 -> ×
I42: 3 | J42: ='2'!N44 -> ×
I43: 4 | J43: ='2'!N45 -> ×
I44: 5 | J44: ='2'!N46 -> ×
